tests/mediumHard/mediumHard_45.in
15
o
12 S 101 GEGS 457 24
12 S 103 GORN 133 929
13 B 104 GLIN 711 783
13 B 105 CONC 815 841
13 B 106 AAIN 1800 948
0 S 107 BDD 1791 388
9 S 109 GORN 1161 469
8 S 110 CONC 223 155
2 S 111 STRA 968 728
6 B 112 STRIPE 1541 349
0 C 107
5 S 114 AAM 1132 613
9 S 115 STRIPE 753 68
7 B 116 THRONE 1567 215
3 S 117 GEGS 644 138
4 S 118 GORN 1885 97
7 C 116
3 C 117
11 B 121 AAO 1853 38
11 S 122 HAHEOD 536 516
12 B 123 FEG 716 303
0 S 124 HAHEOD 360 357
9 C 109
6 C 112
12 S 127 AAC 500 73
12 C 101
0 B 129 GEGS 1698 169
13 B 130 AAIN 1286 311
0 S 131 AAC 405 915
5 B 132 AAM 473 338
14 B 133 STRIPE 408 329
0 S 134 STRIPE 1905 90
3 B 135 THRONE 1024 867
4 B 136 GLIN 1961 423
12 B 137 GORN 1038 685
1 S 138 CAE 835 756
7 C 116
9 C 109
14 B 141 AAIE 923 184
6 S 142 AAN 864 611
4 C 118
2 S 144 AAID 1580 838
6 B 145 AAIE 1963 100
9 B 146 GORN 109 643
7 C 116
5 S 148 AAIC 836 825
1 B 149 A 1749 598
3 B 150 AA 1372 249
11 S 151 BDD 1515 790
14 B 152 AAC 1816 650
10 B 153 AAO 590 701
11 C 151
3 B 155 GORN 1113 851
3 S 156 STRA 701 670
5 S 157 AAIE 1857 286
8 S 158 AAIE 343 374
8 S 159 CAE 1395 953
4 C 136
10 B 161 FEG 761 285
7 C 116
10 B 163 A 1758 51
9 C 115
11 S 165 DOOR 833 941
4 S 166 GEGS 173 31
1 B 167 BDD 465 89
11 S 168 AAIC 726 776
7 S 169 AAID 1984 266
9 S 170 AA 366 327
6 B 171 VIDE 1542 600
5 B 172 AAID 239 551
1 S 173 GORN 901 472
0 S 174 GORN 789 828
9 C 115
9 B 176 AAN 1255 99
9 S 177 AAM 1611 685
14 B 178 AAIE 327 161
11 B 179 GEGS 679 649
3 B 180 AAIN 1607 847
12 C 137
5 C 114
4 S 183 BDD 1829 550
0 B 184 STRIPE 614 761
3 B 185 GORN 1881 539
2 B 186 CAE 724 122
9 S 187 CAE 854 997
8 B 188 GLIN 1683 808
8 C 110
0 C 107
9 B 191 AAN 624 344
7 B 192 BDD 926 850
11 S 193 A 194 374
8 C 110
5 C 114
11 B 196 CONC 1269 405
3 S 197 AAIC 759 28
11 C 196
10 S 199 DOOR 839 206
1 B 200 FEG 1973 919
2 S 201 GORN 1445 960
6 B 202 AAIN 1770 889
4 B 203 AAID 1998 636
13 C 104
11 C 193
0 S 206 VIDE 1702 226
6 S 207 AA 771 683
13 C 130
0 C 174
6 B 210 GORN 341 228
7 S 211 THRONE 1301 343
2 S 212 CONC 1435 989
6 B 213 BDD 1304 586
10 B 214 AAC 789 333
11 S 215 AAIE 1637 171
4 B 216 AAIN 404 641
1 B 217 GORN 1988 949
4 B 218 A 1406 897
11 B 219 AAIN 299 478
5 C 132
3 S 221 GORN 759 840
9 B 222 AAIE 1416 428
11 B 223 GORN 124 218
5 C 157
4 B 225 CONC 1145 905
7 C 116
10 C 153
6 S 228 GLIN 1220 958
13 S 229 FEG 1122 823
6 S 230 GORN 1975 860
5 S 231 STRIPE 964 847
8 S 232 AAM 1423 699
7 B 233 GLIN 1988 951
10 B 234 AAN 1025 378
12 C 137
7 S 236 CONC 883 578
4 S 237 STRIPE 1427 474
4 S 238 AAID 995 253
13 C 106
0 B 240 VIDE 1281 17
7 C 169
1 C 173
5 S 243 AAIC 479 332
6 B 244 STRA 1704 410
3 C 150
9 B 246 AAO 1946 865
1 S 247 BDD 254 787
7 S 248 AAO 547 854
12 C 101
8 B 250 VIDE 1966 413
6 S 251 BDD 417 462
14 S 252 FEG 1316 603
2 B 253 GORN 1953 785
11 C 122
3 S 255 AAIC 1246 678
2 S 256 GEGS 1223 65
6 S 257 A 733 307
12 C 123
11 S 259 THRONE 1573 891
2 B 260 AAIE 236 395
12 B 261 GORN 885 768
4 C 166
6 C 257
3 B 264 STRIPE 325 196
0 B 265 GORN 890 446
0 C 240
1 B 267 AAN 711 802
14 S 268 DOOR 227 427
10 B 269 STRIPE 463 56
6 B 270 AAIN 266 178
6 C 112
13 C 106
3 B 273 AAM 1868 394
2 C 256
13 B 275 STRIPE 945 793
13 C 105
11 S 277 GORN 1593 945
14 C 133
13 C 130
10 S 280 GEGS 527 400
5 C 231
2 B 282 CAE 1518 951
1 S 283 DOOR 1877 74
13 B 284 GORN 642 93
10 S 285 FEG 1232 776
12 S 286 THRONE 1753 23
0 C 107
1 C 247
3 C 117
2 B 290 AAN 185 885
13 B 291 VIDE 1106 18
13 S 292 GLIN 921 602
10 B 293 A 782 14
3 C 185
7 S 295 STRIPE 1515 900
11 B 296 THRONE 1807 340
9 B 297 AAM 1892 129
1 C 247
0 B 299 GORN 461 971
12 B 300 HAHEOD 1283 763
3 C 155
2 C 260
7 S 303 AAM 1457 113
13 C 104
12 S 305 BDD 1494 451
4 S 306 AAIC 806 877
5 B 307 GEGS 1871 478
7 C 236
0 B 309 A 1257 670
8 B 310 FEG 1791 476
2 C 144
13 B 312 GORN 1130 50
6 B 313 STRIPE 1356 572
6 C 244
12 B 315 STRIPE 1712 221
5 S 316 AAIN 1192 861
13 B 317 AA 1292 562
8 B 318 GLIN 760 852
2 B 319 A 1568 139
14 S 320 STRA 1084 304
11 C 121
9 C 177
1 C 149
14 C 141
14 C 152
3 S 326 AAM 1316 484
3 B 327 DOOR 1714 371
2 C 201
0 C 174
3 S 330 AAIN 1476 986
1 B 331 STRIPE 1797 997
4 S 332 AAIE 570 278
3 S 333 GORN 1290 115
11 B 334 STRA 219 73
1 C 200
11 S 336 AAO 892 634
4 S 337 AAIN 224 469
4 S 338 AAID 1351 986
8 B 339 STRIPE 355 32
7 C 295
4 S 341 DOOR 1243 79
0 C 129
8 C 159
8 S 344 AAC 1231 538
11 B 345 THRONE 1531 664
10 S 346 STRIPE 1014 155
5 S 347 DOOR 412 714
1 S 348 STRA 1181 212
4 B 349 GORN 142 861
6 S 350 AAIN 162 209
2 B 351 DOOR 1849 122
11 C 168
11 B 353 AAN 1300 256
10 S 354 HAHEOD 880 586
8 C 339
5 C 132
14 B 357 HAHEOD 1887 190
13 S 358 GORN 843 202
7 C 192
5 B 360 AAID 1493 417
1 C 217
11 S 362 DOOR 1660 424
12 C 305
3 C 185
10 C 163
2 C 351
3 S 367 AAM 1278 295
3 S 368 BDD 1883 614
12 B 369 AAO 901 797
9 B 370 BDD 1822 124
5 B 371 AAIN 1304 752
9 S 372 FEG 306 59
11 B 373 BDD 740 860
6 B 374 GORN 694 571
8 C 310
6 C 270
9 B 377 AAN 1212 342
12 C 305
4 B 379 STRA 1836 987
6 B 380 CONC 1789 852
5 C 360
10 C 214
7 S 383 AAN 478 259
6 C 257
7 S 385 THRONE 1073 773
13 C 291
13 B 387 AAID 518 84
7 C 385
1 B 389 CONC 1174 485
3 B 390 AAN 787 882
10 C 161
13 C 106
11 S 393 VIDE 1885 542
10 B 394 HAHEOD 1875 316
10 S 395 GLIN 1032 143
10 S 396 AAIN 832 829
4 B 397 FEG 438 507
4 B 398 A 480 652
0 S 399 THRONE 720 566
11 B 400 AAO 1822 420
0 C 129
14 S 402 GORN 755 449
2 S 403 GLIN 110 372
4 B 404 AAID 837 292
1 B 405 HAHEOD 1122 357
5 B 406 HAHEOD 1820 947
14 C 178
11 B 408 GLIN 225 87
14 S 409 AAIE 1533 725
12 S 410 STRIPE 1665 124
9 S 411 STRA 1988 547
9 C 411
5 B 413 AAIN 1802 854
1 B 414 AAIN 821 480
6 S 415 GORN 1436 168
11 B 416 AAM 168 719
3 C 367
9 B 418 THRONE 1192 531
3 S 419 AAIN 1918 804
3 B 420 A 1901 437
9 S 421 STRIPE 1773 732
5 B 422 GLIN 573 816
4 B 423 AAID 1846 354
2 C 111
6 B 425 A 1899 714
13 S 426 GLIN 851 358
0 B 427 GORN 1772 448
10 C 280
7 B 429 CAE 1949 593
4 S 430 BDD 813 764
14 C 357
11 B 432 VIDE 1831 292
2 S 433 BDD 762 556
3 C 419
0 C 240
14 S 436 VIDE 1613 373
1 C 267
5 B 438 AAM 955 319
1 S 439 GEGS 1005 710
5 S 440 AAIN 206 82
10 S 441 THRONE 144 87
14 C 357
9 B 443 GEGS 509 760
10 C 354
0 C 265
0 S 446 AAN 586 913
8 S 447 FEG 1183 20
3 B 448 GEGS 1042 607
4 B 449 BDD 527 656
12 S 450 AAC 1141 633
2 S 451 CAE 1215 787
0 B 452 GORN 630 272
13 S 453 CAE 476 716
11 S 454 AAC 1312 132
3 S 455 AAC 1157 964
6 S 456 FEG 721 180
2 C 186
11 S 458 CONC 442 784
11 B 459 DOOR 520 646
7 B 460 DOOR 211 747
1 B 461 CONC 354 498
4 S 462 AAM 1429 799
13 B 463 AAIN 1868 469
5 S 464 AAIN 1752 498
7 S 465 VIDE 1282 887
4 B 466 AAO 477 604
14 B 467 AAIE 1676 654
12 B 468 AAID 1578 315
8 B 469 GORN 1170 632
7 S 470 AAID 1272 193
3 C 150
10 B 472 BDD 650 588
8 S 473 AAO 598 871
11 S 474 GORN 1732 942
9 B 475 AAO 581 709
9 C 170
12 B 477 AAN 432 809
13 S 478 THRONE 1938 850
2 S 479 STRIPE 589 363
10 S 480 GORN 1401 859
12 C 261
3 B 482 GORN 269 982
7 C 460
1 B 484 DOOR 424 337
4 S 485 AAN 1054 272
9 B 486 AAM 636 707
6 S 487 STRA 498 694
4 C 485
4 B 489 HAHEOD 1091 326
2 S 490 HAHEOD 780 796
10 C 480
7 C 295
5 C 422
1 B 494 AAIN 1974 415
13 C 453
10 B 496 AAM 371 379
10 C 496
14 S 498 AA 1625 264
8 C 110
12 S 500 HAHEOD 371 928
3 B 501 AAID 119 597
1 B 502 STRIPE 1799 546
3 C 180
12 B 504 DOOR 1696 79
3 S 505 AAC 1868 280
13 C 291
5 C 307
11 C 296
9 S 509 CAE 1554 772
14 S 510 FEG 873 169
0 S 511 STRIPE 1587 379
12 C 261
14 B 513 AAIN 908 777
13 C 463
0 S 515 AAN 837 94
7 S 516 HAHEOD 926 362
6 C 210
10 B 518 AAO 1113 810
1 C 414
3 S 520 GORN 168 258
6 S 521 AAO 1534 797
5 S 522 AAIE 1481 179
6 S 523 AAN 1319 316
9 C 443
6 B 525 AAID 655 117
11 S 526 A 1335 595
14 B 527 AA 867 406
7 B 528 AAO 381 983
6 S 529 VIDE 142 748
2 S 530 VIDE 1499 200
0 C 446
2 S 532 AAN 782 10
5 C 157
3 C 155
7 B 535 GORN 532 910
9 S 536 GORN 1226 328
12 S 537 THRONE 449 329
9 C 411
5 C 172
0 S 540 DOOR 1348 418
0 C 399
6 C 257
4 B 543 AAIC 883 710
12 S 544 HAHEOD 355 120
14 B 545 AAIE 1293 684
1 S 546 THRONE 1554 977
4 S 547 AAN 1323 637
11 S 548 BDD 1103 442
5 C 316
12 C 123
0 S 551 AAM 243 260
10 C 161
3 S 553 CAE 544 525
8 C 158
5 C 522
