tests/mediumHard/mediumHard_46.in
15
o
1 S 102 AA 1157 198
9 S 103 AAIN 1046 440
9 B 104 AAM 1683 164
1 C 102
9 C 104
7 S 108 FEG 1668 601
5 B 109 AAN 459 966
5 B 111 AAIN 979 704
6 S 112 AA 734 895
12 B 113 DOOR 709 208
2 S 115 AAM 1648 664
2 C 115
8 S 117 THRONE 1541 867
13 S 118 STRIPE 871 619
8 B 119 AA 604 375
5 S 120 GEGS 576 453
1 C 102
9 C 103
1 S 123 BDD 247 927
5 C 109
5 C 120
10 S 126 AA 1836 365
6 B 127 DOOR 575 549
14 S 128 AAIE 231 495
7 C 108
2 B 130 VIDE 1273 221
2 S 131 BDD 411 649
6 S 132 AAIC 442 389
10 S 133 GORN 1502 400
0 S 134 DOOR 108 668
6 S 135 AAIE 549 912
6 C 112
0 C 134
7 S 138 BDD 194 401
7 S 139 DOOR 588 202
4 S 140 GORN 1906 627
6 S 141 AA 1929 169
11 S 142 GORN 1694 711
4 S 143 GORN 349 668
14 C 128
5 S 145 VIDE 1605 779
2 S 146 THRONE 321 656
6 C 132
14 C 128
4 S 149 AAN 1897 615
13 B 150 AAN 1615 532
14 C 128
2 B 152 A 1971 338
11 B 153 HAHEOD 1464 338
11 B 154 STRA 633 75
2 B 155 VIDE 1182 87
4 S 156 AAIN 1348 342
12 B 157 A 1781 505
9 S 158 GORN 1242 44
13 C 150
14 B 160 THRONE 1918 83
0 C 134
10 C 126
7 S 163 DOOR 194 569
9 C 158
11 S 165 AA 533 42
14 S 166 AAID 1743 352
1 C 102
0 B 169 AAIE 1944 982
11 S 170 A 957 191
3 S 171 FEG 1473 493
5 C 145
9 C 158
1 B 174 AAIC 1607 23
13 C 118
8 S 176 GORN 1431 764
7 C 139
2 C 131
12 B 179 BDD 1012 868
8 C 117
13 B 181 AAIC 105 476
6 B 182 GORN 1826 821
13 C 118
1 B 184 CAE 479 377
9 B 185 AAN 1552 488
1 B 186 AAC 325 515
7 C 139
5 C 109
13 B 189 AAIC 940 700
5 S 190 GORN 1865 876
9 B 191 CAE 1606 537
4 S 192 AAID 880 684
0 C 169
4 B 194 AAC 750 598
2 S 195 AAN 502 377
0 C 169
2 C 146
1 C 174
9 C 191
14 B 200 AAID 1017 230
8 S 201 AAC 926 380
10 C 126
8 C 201
14 C 160
0 S 205 AAM 1478 176
14 B 206 GLIN 1303 434
2 C 115
3 C 171
12 S 209 CAE 1850 485
12 S 210 VIDE 1408 589
2 S 211 BDD 1592 975
5 C 190
7 S 213 CAE 197 270
4 S 214 AAID 342 503
12 B 215 GORN 221 323
2 B 216 THRONE 898 164
12 B 217 GORN 1571 878
4 B 218 CAE 1237 196
11 B 219 VIDE 1415 134
10 C 126
12 B 221 FEG 260 306
11 C 170
2 C 130
9 C 158
8 S 225 AAIN 240 441
8 S 226 CAE 146 22
4 B 227 FEG 1057 363
10 S 228 GORN 1202 694
6 C 112
12 S 230 AAO 269 589
11 B 231 AA 840 98
13 C 189
5 S 233 GORN 1361 331
14 B 234 VIDE 978 492
7 C 138
2 S 236 AAN 1376 493
11 B 237 GORN 1086 391
3 S 238 STRA 1095 447
4 B 239 GEGS 1472 704
2 C 155
3 C 171
3 B 242 STRIPE 239 309
5 C 190
11 C 165
14 S 245 FEG 1268 448
6 B 246 GEGS 1805 117
9 C 158
6 B 248 AAN 927 601
7 C 139
0 B 250 THRONE 319 331
2 B 251 AAIN 839 934
2 S 252 AAO 243 51
0 C 250
12 C 215
1 C 123
11 B 256 STRA 504 784
2 S 257 AAIE 1315 925
12 B 258 THRONE 832 293
5 S 259 STRA 397 118
4 S 260 AA 1924 19
2 B 261 AAIC 514 328
11 B 262 A 451 390
10 C 126
12 C 210
3 S 265 GORN 1455 728
9 C 104
10 S 267 THRONE 360 165
8 S 268 GEGS 1068 854
0 C 250
7 B 270 AAM 212 524
9 C 185
14 C 160
11 B 273 CONC 1696 608
10 B 274 GORN 1188 694
11 S 275 DOOR 593 261
11 C 273
4 B 277 A 388 600
4 S 278 GEGS 375 925
1 S 279 STRA 466 66
1 S 280 DOOR 344 911
6 S 281 CONC 618 682
9 S 282 AAO 1448 549
12 B 283 AAN 1750 71
3 S 284 A 1607 473
1 S 285 GORN 1241 855
6 C 112
14 S 287 AA 1214 280
10 B 288 THRONE 1205 337
14 B 289 CONC 424 224
12 C 179
9 B 291 DOOR 403 47
13 B 292 GORN 513 715
5 S 293 AAO 1297 202
8 C 268
4 C 278
12 B 296 AAM 273 639
10 S 297 GORN 1783 931
3 B 298 DOOR 521 397
6 B 299 THRONE 968 926
7 B 300 BDD 1927 912
5 B 301 STRIPE 1309 691
11 S 302 BDD 1234 823
13 S 303 AAID 580 969
14 C 234
1 S 305 AAID 882 294
6 B 306 VIDE 447 272
7 B 307 GORN 1593 857
7 S 308 STRIPE 1025 960
2 S 309 AAID 1375 570
3 C 238
5 B 311 GEGS 438 575
10 S 312 GORN 1393 59
2 C 152
9 S 314 GEGS 630 556
9 B 315 STRIPE 680 672
5 C 109
2 C 152
7 S 318 GEGS 374 451
13 C 150
7 C 108
11 C 262
11 B 322 CAE 198 447
12 B 323 AAO 721 128
9 S 324 AA 1541 810
9 B 325 AAIE 555 794
9 B 326 BDD 575 469
8 C 176
6 S 328 AAM 783 594
12 S 329 GORN 424 616
1 B 330 DOOR 1237 501
3 B 331 DOOR 246 701
8 B 332 STRA 844 717
10 B 333 AAN 1883 214
0 B 334 AAIN 658 792
5 S 335 VIDE 1648 197
3 B 336 AAM 1529 99
7 C 163
13 B 338 DOOR 353 19
6 S 339 GORN 1501 224
11 S 340 AAM 1896 926
1 S 341 GORN 883 645
8 B 342 AAIN 1002 50
4 S 343 BDD 1682 217
11 C 237
7 B 345 AAO 338 206
4 C 149
7 S 347 GORN 1617 249
12 S 348 GEGS 1908 187
7 S 349 CAE 1541 792
5 C 190
14 S 351 DOOR 1107 312
12 S 352 GEGS 1653 172
14 B 353 GEGS 1214 461
9 S 354 A 1522 688
7 C 345
14 B 356 CAE 328 999
14 C 289
12 B 358 CAE 839 558
2 S 359 GEGS 1714 965
0 S 360 FEG 1865 335
2 C 309
2 S 362 AAN 1967 351
13 C 189
9 S 364 AAN 1441 145
6 B 365 THRONE 1796 599
13 S 366 AAIC 1107 613
12 B 367 AA 863 744
7 B 368 GEGS 1695 929
5 C 311
13 S 370 THRONE 1872 344
4 B 371 VIDE 895 816
13 S 372 AAC 340 75
12 B 373 STRA 225 528
3 B 374 AAO 258 956
0 B 375 GORN 1175 798
7 B 376 BDD 1563 870
8 S 377 AAIE 1441 724
11 C 165
13 C 189
12 C 157
3 S 381 GEGS 1759 697
3 S 382 VIDE 1965 196
5 S 383 VIDE 375 959
10 B 384 AAN 266 720
7 S 385 AAIC 935 15
12 S 386 AAO 1795 761
6 B 387 AAM 134 40
14 C 166
9 C 185
6 S 390 AAIN 1826 261
3 S 391 FEG 1867 428
9 C 326
4 S 393 BDD 968 610
7 S 394 STRIPE 118 290
6 C 390
2 C 146
11 S 397 FEG 144 543
12 B 398 VIDE 858 162
13 C 150
7 S 400 CAE 1843 771
10 S 401 A 1692 725
2 B 402 AAM 265 840
8 C 225
2 B 404 AAIC 1277 164
11 S 405 BDD 1267 76
14 C 353
6 S 407 AAM 1430 165
12 C 373
5 S 409 STRA 335 820
6 B 410 A 998 842
9 B 411 HAHEOD 325 398
10 C 267
10 C 133
7 B 414 DOOR 1094 603
0 B 415 AA 1655 724
3 C 336
11 C 302
9 B 418 AA 1814 297
6 S 419 AAM 686 505
3 C 391
14 B 421 DOOR 1774 255
2 C 216
9 S 423 AAIE 1685 53
9 B 424 GEGS 1949 963
2 B 425 FEG 267 697
7 S 426 AAIN 1044 92
7 C 394
12 C 179
9 S 429 GORN 586 524
9 S 430 AAN 536 628
12 B 431 AAIE 248 209
6 C 112
14 C 206
10 B 434 HAHEOD 599 305
0 B 435 AAN 434 109
3 S 436 A 1162 408
14 C 245
10 S 438 AAIC 354 238
0 B 439 GORN 1974 46
2 B 440 AAO 1989 646
12 S 441 AAID 1648 879
13 C 150
14 B 443 AAID 500 706
7 B 444 STRA 502 745
13 B 445 GEGS 435 766
4 S 446 A 1239 914
0 B 447 GEGS 1110 384
13 C 181
6 S 449 STRA 1836 859
8 B 450 A 425 34
0 B 451 VIDE 1601 450
7 C 270
5 B 453 GLIN 417 112
11 B 454 AAM 1967 908
6 C 407
0 B 456 FEG 407 566
8 B 457 DOOR 702 364
4 C 192
13 B 459 AAID 596 724
9 C 315
5 B 461 AAN 477 666
0 S 462 STRA 1784 144
10 S 463 AAN 530 619
3 S 464 AAID 754 34
13 B 465 THRONE 1865 579
5 B 466 CAE 835 739
8 C 268
11 C 219
13 S 469 GORN 1816 427
11 S 470 AAIE 165 223
2 C 130
14 S 472 AAIN 1389 403
8 S 473 STRA 692 230
11 B 474 AA 1606 326
13 S 475 AAIE 268 496
2 B 476 AAN 783 470
5 C 259
13 C 445
14 B 479 STRIPE 592 723
4 S 480 STRIPE 1055 683
11 C 340
1 C 330
10 S 483 FEG 1915 481
1 B 484 AAC 1289 253
8 S 485 GLIN 1226 218
4 C 343
4 B 487 BDD 1043 337
7 S 488 GLIN 171 730
5 C 453
8 B 490 GEGS 1543 460
7 C 108
9 S 492 FEG 1746 624
4 S 493 AAIE 497 783
11 S 494 AAM 306 749
4 B 495 CAE 1499 790
7 S 496 AAC 1669 511
3 C 171
4 S 498 VIDE 1776 803
10 B 499 A 1420 603
7 S 500 AAIC 1579 989
12 B 501 AAIN 1919 786
0 B 502 AAIC 484 379
11 B 503 STRIPE 1381 614
13 B 504 AAIC 1405 52
5 C 120
6 S 506 BDD 628 326
14 B 507 HAHEOD 1966 604
11 C 397
3 B 509 BDD 1509 488
13 B 510 CONC 1400 462
7 B 511 STRIPE 1964 235
12 B 512 AAO 1086 316
6 B 513 AAIC 807 786
4 C 277
12 C 210
0 B 516 AAID 1567 51
8 S 517 AAO 229 911
3 S 518 AAN 702 480
4 S 519 AAIC 803 597
10 B 520 GEGS 1977 257
2 C 115
11 C 231
14 B 523 CAE 1398 169
10 S 524 THRONE 1922 418
4 B 525 CONC 129 700
8 B 526 DOOR 964 161
13 S 527 AAC 1097 199
3 B 528 AAID 1025 82
12 C 441
11 C 273
1 B 531 AAN 142 500
8 B 532 CONC 225 298
5 C 301
9 C 354
7 B 535 THRONE 448 555
0 S 536 GLIN 223 349
7 C 318
9 B 538 BDD 1797 215
12 B 539 HAHEOD 1476 364
2 B 540 AAN 1071 562
13 S 541 STRA 1005 158
9 S 542 AA 1559 606
9 B 543 AAIC 576 155
2 B 544 AAO 1626 437
11 S 545 HAHEOD 1124 500
10 S 546 AA 1626 989
5 C 466
13 B 548 DOOR 390 806
14 S 549 GLIN 905 913
0 S 550 CONC 1660 284
3 S 551 STRA 1601 205
14 B 552 AAIE 734 119
2 B 553 DOOR 235 618
4 S 554 AAID 1535 566
13 S 555 CAE 367 597
3 S 556 HAHEOD 1248 986
4 C 519
14 C 351
1 B 559 AAIC 1910 166
6 B 560 GORN 392 536
4 C 140
1 S 562 STRA 1832 457
9 B 563 STRIPE 936 598
